<?xml version="1.0"?>
<robot name="scara">

  <material name="yellow">
    <color rgba="0.8 0.8 0 0.5"/>
  </material>
  <material name="blue">
    <color rgba="0 0 0.8 0.5"/>
  </material>
  <material name="red">
    <color rgba="0.8 0 0 0.5"/>
  </material>
  <material name="green">
    <color rgba="0 0.8 0 0.5"/>
  </material>

  <link name="base_link">
    <visual>
      <origin xyz="0 0 0.25"/>
      <geometry>
        <cylinder length="0.5" radius="0.2"/>
      </geometry>
      <material name="yellow"/>
    </visual>
  </link>

  <link name="link1">
    <visual>
      <geometry>
        <box size="2.0 0.4 0.5"/>
      </geometry>
      <origin xyz="1 0 -0.25"/>
      <material name="blue"/>
    </visual>
  </link>

  <link name="link1_visual">
    <visual>
      <geometry>
        <cylinder length="0.5" radius="0.2"/>
      </geometry>
      <origin xyz="0 0 0"/>
      <material name="blue"/>
    </visual>
  </link>

  <joint name="base_link_to_link1" type="continuous">
    <parent link="base_link"/>
    <child link="link1"/>
    <axis xyz="0 0 1"/>
    <origin xyz="0 0 1"/>
  </joint>

  <joint name="link1_to_link1_visual" type="fixed">
    <parent link="link1"/>
    <child link="link1_visual"/>
    <origin xyz="0 0 -0.25"/>
  </joint>

  <link name="link2">
    <visual>
      <geometry>
        <box size="2.0 0.4 0.5"/>
      </geometry>
      <origin xyz="1 0 -0.25"/>
      <material name="red"/>
    </visual>
  </link>

  <link name="link2_visual">
    <visual>
      <geometry>
        <cylinder length="0.5" radius="0.2"/>
      </geometry>
      <origin xyz="0 0 0"/>
      <material name="red"/>
    </visual>
  </link>

  <link name="link2_visual2">
    <visual>
      <geometry>
        <cylinder length="0.5" radius="0.2"/>
      </geometry>
      <origin xyz="0 0 0"/>
      <material name="red"/>
    </visual>
  </link>

  <joint name="link1_to_link2" type="continuous">
    <parent link="link1"/>
    <child link="link2"/>
    <axis xyz="0 0 1"/>
    <origin xyz="2 0 0"/>
  </joint>

  <joint name="link2_to_link2_visual" type="fixed">
    <parent link="link2"/>
    <child link="link2_visual"/>
    <origin xyz="0 0 -0.25"/>
  </joint>

  <joint name="link2_to_link2_visual2" type="fixed">
    <parent link="link2"/>
    <child link="link2_visual2"/>
    <origin xyz="2 0 -0.25"/>
  </joint>

  <link name="ee_link">
    <visual>
      <geometry>
        <cylinder length="1" radius="0.1"/>
      </geometry>
      <origin xyz="0 0 -0.5"/>
      <material name="green"/>
    </visual>
  </link>

  <joint name="link2_to_ee_link" type="prismatic">
    <axis xyz="0 0 -1"/>
    <limit effort="1000.0" lower="0" upper="0.5" velocity="0.5"/>
    <origin xyz="2 0 0"/>
    <parent link="link2"/>
    <child link="ee_link"/>
  </joint>

</robot>